Traceback (most recent call last):
  File "/usr/share/miniconda3/envs/gu-psyc-347-jb/lib/python3.7/site-packages/jupyter_cache/executors/utils.py", line 56, in single_nb_execution
    record_timing=False,
  File "/usr/share/miniconda3/envs/gu-psyc-347-jb/lib/python3.7/site-packages/nbclient/client.py", line 1117, in execute
    return NotebookClient(nb=nb, resources=resources, km=km, **kwargs).execute()
  File "/usr/share/miniconda3/envs/gu-psyc-347-jb/lib/python3.7/site-packages/nbclient/util.py", line 78, in wrapped
    return just_run(coro(*args, **kwargs))
  File "/usr/share/miniconda3/envs/gu-psyc-347-jb/lib/python3.7/site-packages/nbclient/util.py", line 57, in just_run
    return loop.run_until_complete(coro)
  File "/usr/share/miniconda3/envs/gu-psyc-347-jb/lib/python3.7/asyncio/base_events.py", line 587, in run_until_complete
    return future.result()
  File "/usr/share/miniconda3/envs/gu-psyc-347-jb/lib/python3.7/site-packages/nbclient/client.py", line 559, in async_execute
    cell, index, execution_count=self.code_cells_executed + 1
  File "/usr/share/miniconda3/envs/gu-psyc-347-jb/lib/python3.7/site-packages/nbclient/client.py", line 862, in async_execute_cell
    self._check_raise_for_error(cell, exec_reply)
  File "/usr/share/miniconda3/envs/gu-psyc-347-jb/lib/python3.7/site-packages/nbclient/client.py", line 765, in _check_raise_for_error
    raise CellExecutionError.from_cell_and_msg(cell, exec_reply_content)
nbclient.exceptions.CellExecutionError: An error occurred while executing the following cell:
------------------
# minimize MSE using scipy.optimize.minimize
res = minimize(mse_to_minimize, # objective function
               (350, -1.75), # estimated starting points
               args=(X, y)) # arguments

print(f'b0, b1 = {(res.x)}, MSE = {res.fun}')
plot_observed_vs_predicted([res.x[0], res.x[1]], X, y)
------------------

[0;31m---------------------------------------------------------------------------[0m
[0;31mNameError[0m                                 Traceback (most recent call last)
[0;32m/tmp/ipykernel_4621/2049133039.py[0m in [0;36m<module>[0;34m[0m
[1;32m      5[0m [0;34m[0m[0m
[1;32m      6[0m [0mprint[0m[0;34m([0m[0;34mf'b0, b1 = {(res.x)}, MSE = {res.fun}'[0m[0;34m)[0m[0;34m[0m[0;34m[0m[0m
[0;32m----> 7[0;31m [0mplot_observed_vs_predicted[0m[0;34m([0m[0;34m[[0m[0mres[0m[0;34m.[0m[0mx[0m[0;34m[[0m[0;36m0[0m[0;34m][0m[0;34m,[0m [0mres[0m[0;34m.[0m[0mx[0m[0;34m[[0m[0;36m1[0m[0;34m][0m[0;34m][0m[0;34m,[0m [0mX[0m[0;34m,[0m [0my[0m[0;34m)[0m[0;34m[0m[0;34m[0m[0m
[0m
[0;31mNameError[0m: name 'plot_observed_vs_predicted' is not defined
NameError: name 'plot_observed_vs_predicted' is not defined

